test_message_1.json
[{"type":"subscriptions","channels":[{"name":"heartbeat","product_ids":["BTC-USD"]},{"name":"full","product_ids":["BTC-USD"]}]},{"order_id":"ac6368fb-ea9f-4c74-b8ba-9c61056ab719","order_type":"limit","size":"0.00989427","price":"18882.2","client_oid":"10581200-0000-0000-0000-58aba786d265","type":"received","side":"sell","product_id":"BTC-USD","time":"2022-09-26T03:10:27.067787Z","sequence":46723058843},{"price":"18882.2","order_id":"ac6368fb-ea9f-4c74-b8ba-9c61056ab719","remaining_size":"0.00989427","type":"open","side":"sell","product_id":"BTC-USD","time":"2022-09-26T03:10:27.067787Z","sequence":46723058844},{"order_id":"cae812d3-ea79-49ea-97c6-bda5e7219986","reason":"canceled","price":"18900.29","remaining_size":"0.15674279","type":"done","side":"sell","product_id":"BTC-USD","time":"2022-09-26T03:10:27.114403Z","sequence":46723058845},{"order_id":"a13ea032-2603-4118-98f5-cfbb5ecaa1ca","reason":"canceled","price":"18881.73","remaining_size":"0.0924925","type":"done","side":"buy","product_id":"BTC-USD","time":"2022-09-26T03:10:27.124102Z","sequence":46723058846},{"order_id":"4c1074ea-6e1a-4de3-a094-092fd089105f","reason":"canceled","price":"18881.73","remaining_size":"0.015","type":"done","side":"buy","product_id":"BTC-USD","time":"2022-09-26T03:10:27.131276Z","sequence":46723058847},{"order_id":"f62b182a-55ac-45bf-a0b3-5b82fb5b4bf2","order_type":"limit","size":"0.02684411","price":"18878.53","client_oid":"45b1836a-60af-4a7e-b955-e2c7228ee7c7","type":"received","side":"buy","product_id":"BTC-USD","time":"2022-09-26T03:10:27.132342Z","sequence":46723058848},{"price":"18878.53","order_id":"f62b182a-55ac-45bf-a0b3-5b82fb5b4bf2","remaining_size":"0.02684411","type":"open","side":"buy","product_id":"BTC-USD","time":"2022-09-26T03:10:27.132342Z","sequence":46723058849},{"order_id":"38254980-a1da-419b-af03-af7b9221d1ad","reason":"canceled","price":"18881.06","remaining_size":"0.02648155","type":"done","side":"buy","product_id":"BTC-USD","time":"2022-09-26T03:10:27.134685Z","sequence":46723058850},{"order_id":"a53cd2a6-13e5-4036-9eae-6ce6f21f841d","reason":"canceled","price":"18372","remaining_size":"0.00106983","type":"done","side":"buy","product_id":"BTC-USD","time":"2022-09-26T03:10:27.137000Z","sequence":46723058851},{"order_id":"1cc92d86-f09f-4159-9d10-c366e10244f0","reason":"canceled","price":"18883.82","remaining_size":"0.0264777","type":"done","side":"sell","product_id":"BTC-USD","time":"2022-09-26T03:10:27.140730Z","sequence":46723058852},{"order_id":"be28fb8b-10c9-4d22-ab6c-ce0977b329cf","reason":"canceled","price":"18882.2","remaining_size":"0.03233509","type":"done","side":"sell","product_id":"BTC-USD","time":"2022-09-26T03:10:27.141058Z","sequence":46723058853}]
