test_message_2.json
[{"type":"subscriptions","channels":[{"name":"heartbeat","product_ids":["BTC-USD"]},{"name":"full","product_ids":["BTC-USD"]}]},{"order_id":"7b93564e-89e8-46fa-ac15-6a8a99dcd77d","reason":"canceled","price":"18893.86","remaining_size":"0.1","type":"done","side":"sell","product_id":"BTC-USD","time":"2022-09-26T03:21:04.768065Z","sequence":46723450552},{"order_id":"54844d02-c2b5-450c-994d-e91985568a90","reason":"canceled","price":"18892.03","remaining_size":"0.00852604","type":"done","side":"sell","product_id":"BTC-USD","time":"2022-09-26T03:21:04.779300Z","sequence":46723450553},{"order_id":"fe5e3cda-78e4-4ce0-bdf8-07361227d096","order_type":"limit","size":"0.01256973","price":"18891.92","client_oid":"e63d09a1-5d1b-4385-9f1e-fb7c8a41cf65","type":"received","side":"sell","product_id":"BTC-USD","time":"2022-09-26T03:21:04.790216Z","sequence":46723450554},{"price":"18891.92","order_id":"fe5e3cda-78e4-4ce0-bdf8-07361227d096","remaining_size":"0.01256973","type":"open","side":"sell","product_id":"BTC-USD","time":"2022-09-26T03:21:04.790216Z","sequence":46723450555},{"order_id":"dc83e5de-66df-4b40-9cf3-149916837d16","order_type":"limit","size":"0.61103843","price":"18888.14","client_oid":"103883ba-56f1-4af5-92ff-f990efea0c37","type":"received","side":"buy","product_id":"BTC-USD","time":"2022-09-26T03:21:04.794471Z","sequence":46723450556},{"price":"18888.14","order_id":"dc83e5de-66df-4b40-9cf3-149916837d16","remaining_size":"0.61103843","type":"open","side":"buy","product_id":"BTC-USD","time":"2022-09-26T03:21:04.794471Z","sequence":46723450557},{"order_id":"eb4567e7-5826-4941-9503-aa6bbd62c208","order_type":"limit","size":"0.1","price":"18893.94","client_oid":"412018ca-3d4a-11ed-8b5d-abb0b41c20d0","type":"received","side":"sell","product_id":"BTC-USD","time":"2022-09-26T03:21:04.794501Z","sequence":46723450558},{"price":"18893.94","order_id":"eb4567e7-5826-4941-9503-aa6bbd62c208","remaining_size":"0.1","type":"open","side":"sell","product_id":"BTC-USD","time":"2022-09-26T03:21:04.794501Z","sequence":46723450559},{"order_id":"268b6fcd-7d93-4764-adec-304a429cd987","order_type":"limit","size":"0.61228293","price":"18895.24","client_oid":"ff0cf0c9-1851-46e7-98d0-cecb50867464","type":"received","side":"sell","product_id":"BTC-USD","time":"2022-09-26T03:21:04.794536Z","sequence":46723450560},{"price":"18895.24","order_id":"268b6fcd-7d93-4764-adec-304a429cd987","remaining_size":"0.61228293","type":"open","side":"sell","product_id":"BTC-USD","time":"2022-09-26T03:21:04.794536Z","sequence":46723450561},{"order_id":"3acad7ab-8a3d-424d-affb-5b8f0ae1e4e0","reason":"canceled","price":"18892.84","remaining_size":"0.00306414","type":"done","side":"sell","product_id":"BTC-USD","time":"2022-09-26T03:21:04.935448Z","sequence":46723450562}]
